2025-06-28 13:40:03,115 - INFO - Session Has Been Closed 13:39:52 
2025-06-28 13:40:56,764 - INFO - Authenticated Company Found 
2025-06-28 13:40:56,767 - INFO - Session Has Been Closed 13:39:52 
2025-06-29 11:59:35,881 - INFO - Session Has Been Closed 11:56:02 
2025-06-29 12:01:35,230 - INFO - Session Has Been Closed 11:56:02 
2025-06-29 12:01:52,207 - INFO - Authenticated Company Found 
2025-06-29 12:01:52,211 - INFO - Session Has Been Closed 11:56:02 
2025-06-29 12:05:49,566 - INFO - Session Has Been Closed 12:04:17 
2025-06-29 12:05:49,569 - ERROR - Validation Failed [{'type': 'missing', 'loc': ('body', 'employee_password'), 'msg': 'Field required', 'input': {'employee_email': 'adi@gmail.com', 'employee_name': 'adi', 'password': 'ilove', 'role': 'enginneer'}}, {'type': 'missing', 'loc': ('body', 'join_code'), 'msg': 'Field required', 'input': {'employee_email': 'adi@gmail.com', 'employee_name': 'adi', 'password': 'ilove', 'role': 'enginneer'}}] 
2025-06-29 12:06:10,685 - INFO - Session Has Been Closed 12:04:17 
2025-06-29 12:06:10,685 - ERROR - Validation Failed [{'type': 'missing', 'loc': ('body', 'join_code'), 'msg': 'Field required', 'input': {'employee_email': 'adi@gmail.com', 'employee_name': 'adi', 'employee_password': 'ilove', 'role': 'enginneer'}}] 
2025-06-29 12:06:43,152 - INFO - Authenticated Company Found 
2025-06-29 12:06:43,154 - INFO - Session Has Been Closed 12:04:17 
2025-06-29 12:06:58,242 - ERROR - Error Creating Employee: Neither 'InstrumentedAttribute' object nor 'Comparator' object associated with Company.company_code has an attribute 'lower' 
2025-06-29 12:06:58,242 - INFO - Session Has Been Closed 12:04:17 
2025-06-29 12:06:58,611 - ERROR - [408856ff-cd8a-4e79-91b8-b58302435961] Internal error: Traceback (most recent call last):
  File "C:\Users\SHADO\OneDrive\Desktop\emplyoyeeTracker\env\Lib\site-packages\sqlalchemy\sql\elements.py", line 1506, in __getattr__
    return getattr(self.comparator, key)
           ^^^^^^^^^^^^^^^^^^^^^^^^^^^^^
AttributeError: 'TDComparator' object has no attribute 'lower'

The above exception was the direct cause of the following exception:

Traceback (most recent call last):
  File "C:\Users\SHADO\OneDrive\Desktop\emplyoyeeTracker\env\Lib\site-packages\sqlalchemy\orm\attributes.py", line 472, in __getattr__
    return getattr(self.comparator, key)
           ^^^^^^^^^^^^^^^^^^^^^^^^^^^^^
  File "C:\Users\SHADO\OneDrive\Desktop\emplyoyeeTracker\env\Lib\site-packages\sqlalchemy\util\langhelpers.py", line 1413, in __getattr__
    return self._fallback_getattr(key)
           ^^^^^^^^^^^^^^^^^^^^^^^^^^^
  File "C:\Users\SHADO\OneDrive\Desktop\emplyoyeeTracker\env\Lib\site-packages\sqlalchemy\orm\properties.py", line 474, in _fallback_getattr
    return getattr(self.__clause_element__(), key)
           ^^^^^^^^^^^^^^^^^^^^^^^^^^^^^^^^^^^^^^^
  File "C:\Users\SHADO\OneDrive\Desktop\emplyoyeeTracker\env\Lib\site-packages\sqlalchemy\sql\elements.py", line 1508, in __getattr__
    raise AttributeError(
AttributeError: Neither 'AnnotatedColumn' object nor 'TDComparator' object has an attribute 'lower'

The above exception was the direct cause of the following exception:

Traceback (most recent call last):
  File "C:\Users\SHADO\OneDrive\Desktop\emplyoyeeTracker\env\Lib\site-packages\starlette\middleware\errors.py", line 165, in __call__
    await self.app(scope, receive, _send)
  File "C:\Users\SHADO\OneDrive\Desktop\emplyoyeeTracker\env\Lib\site-packages\starlette\middleware\cors.py", line 85, in __call__
    await self.app(scope, receive, send)
  File "C:\Users\SHADO\OneDrive\Desktop\emplyoyeeTracker\env\Lib\site-packages\starlette\middleware\exceptions.py", line 62, in __call__
    await wrap_app_handling_exceptions(self.app, conn)(scope, receive, send)
  File "C:\Users\SHADO\OneDrive\Desktop\emplyoyeeTracker\env\Lib\site-packages\starlette\_exception_handler.py", line 53, in wrapped_app
    raise exc
  File "C:\Users\SHADO\OneDrive\Desktop\emplyoyeeTracker\env\Lib\site-packages\starlette\_exception_handler.py", line 42, in wrapped_app
    await app(scope, receive, sender)
  File "C:\Users\SHADO\OneDrive\Desktop\emplyoyeeTracker\env\Lib\site-packages\starlette\routing.py", line 714, in __call__
    await self.middleware_stack(scope, receive, send)
  File "C:\Users\SHADO\OneDrive\Desktop\emplyoyeeTracker\env\Lib\site-packages\starlette\routing.py", line 734, in app
    await route.handle(scope, receive, send)
  File "C:\Users\SHADO\OneDrive\Desktop\emplyoyeeTracker\env\Lib\site-packages\starlette\routing.py", line 288, in handle
    await self.app(scope, receive, send)
  File "C:\Users\SHADO\OneDrive\Desktop\emplyoyeeTracker\env\Lib\site-packages\starlette\routing.py", line 76, in app
    await wrap_app_handling_exceptions(app, request)(scope, receive, send)
  File "C:\Users\SHADO\OneDrive\Desktop\emplyoyeeTracker\env\Lib\site-packages\starlette\_exception_handler.py", line 53, in wrapped_app
    raise exc
  File "C:\Users\SHADO\OneDrive\Desktop\emplyoyeeTracker\env\Lib\site-packages\starlette\_exception_handler.py", line 42, in wrapped_app
    await app(scope, receive, sender)
  File "C:\Users\SHADO\OneDrive\Desktop\emplyoyeeTracker\env\Lib\site-packages\starlette\routing.py", line 73, in app
    response = await f(request)
               ^^^^^^^^^^^^^^^^
  File "C:\Users\SHADO\OneDrive\Desktop\emplyoyeeTracker\env\Lib\site-packages\fastapi\routing.py", line 301, in app
    raw_response = await run_endpoint_function(
                   ^^^^^^^^^^^^^^^^^^^^^^^^^^^^
  File "C:\Users\SHADO\OneDrive\Desktop\emplyoyeeTracker\env\Lib\site-packages\fastapi\routing.py", line 212, in run_endpoint_function
    return await dependant.call(**values)
           ^^^^^^^^^^^^^^^^^^^^^^^^^^^^^^
  File "C:\Users\SHADO\OneDrive\Desktop\emplyoyeeTracker\src\routes\EmployeeRouter.py", line 24, in createEmployee
    return await create_employee(employee=employee, session=session)
           ^^^^^^^^^^^^^^^^^^^^^^^^^^^^^^^^^^^^^^^^^^^^^^^^^^^^^^^^^
  File "C:\Users\SHADO\OneDrive\Desktop\emplyoyeeTracker\src\controllers\EmployeeController.py", line 11, in create_employee
    select(Company).where(Company.company_code.lower() == employee.join_code.lower())
                          ^^^^^^^^^^^^^^^^^^^^^^^^^^
  File "C:\Users\SHADO\OneDrive\Desktop\emplyoyeeTracker\env\Lib\site-packages\sqlalchemy\orm\attributes.py", line 474, in __getattr__
    raise AttributeError(
AttributeError: Neither 'InstrumentedAttribute' object nor 'Comparator' object associated with Company.company_code has an attribute 'lower'
 
2025-06-29 12:10:57,260 - INFO - Session Has Been Closed 12:10:47 
2025-06-29 12:11:14,445 - INFO - Session Has Been Closed 12:10:47 
2025-06-29 12:11:14,455 - ERROR - [123b0011-82e3-49e7-adf5-35bebef33141] Internal error: Traceback (most recent call last):
  File "C:\Users\SHADO\OneDrive\Desktop\emplyoyeeTracker\env\Lib\site-packages\starlette\middleware\errors.py", line 165, in __call__
    await self.app(scope, receive, _send)
  File "C:\Users\SHADO\OneDrive\Desktop\emplyoyeeTracker\env\Lib\site-packages\starlette\middleware\cors.py", line 85, in __call__
    await self.app(scope, receive, send)
  File "C:\Users\SHADO\OneDrive\Desktop\emplyoyeeTracker\env\Lib\site-packages\starlette\middleware\exceptions.py", line 62, in __call__
    await wrap_app_handling_exceptions(self.app, conn)(scope, receive, send)
  File "C:\Users\SHADO\OneDrive\Desktop\emplyoyeeTracker\env\Lib\site-packages\starlette\_exception_handler.py", line 53, in wrapped_app
    raise exc
  File "C:\Users\SHADO\OneDrive\Desktop\emplyoyeeTracker\env\Lib\site-packages\starlette\_exception_handler.py", line 42, in wrapped_app
    await app(scope, receive, sender)
  File "C:\Users\SHADO\OneDrive\Desktop\emplyoyeeTracker\env\Lib\site-packages\starlette\routing.py", line 714, in __call__
    await self.middleware_stack(scope, receive, send)
  File "C:\Users\SHADO\OneDrive\Desktop\emplyoyeeTracker\env\Lib\site-packages\starlette\routing.py", line 734, in app
    await route.handle(scope, receive, send)
  File "C:\Users\SHADO\OneDrive\Desktop\emplyoyeeTracker\env\Lib\site-packages\starlette\routing.py", line 288, in handle
    await self.app(scope, receive, send)
  File "C:\Users\SHADO\OneDrive\Desktop\emplyoyeeTracker\env\Lib\site-packages\starlette\routing.py", line 76, in app
    await wrap_app_handling_exceptions(app, request)(scope, receive, send)
  File "C:\Users\SHADO\OneDrive\Desktop\emplyoyeeTracker\env\Lib\site-packages\starlette\_exception_handler.py", line 53, in wrapped_app
    raise exc
  File "C:\Users\SHADO\OneDrive\Desktop\emplyoyeeTracker\env\Lib\site-packages\starlette\_exception_handler.py", line 42, in wrapped_app
    await app(scope, receive, sender)
  File "C:\Users\SHADO\OneDrive\Desktop\emplyoyeeTracker\env\Lib\site-packages\starlette\routing.py", line 73, in app
    response = await f(request)
               ^^^^^^^^^^^^^^^^
  File "C:\Users\SHADO\OneDrive\Desktop\emplyoyeeTracker\env\Lib\site-packages\fastapi\routing.py", line 301, in app
    raw_response = await run_endpoint_function(
                   ^^^^^^^^^^^^^^^^^^^^^^^^^^^^
  File "C:\Users\SHADO\OneDrive\Desktop\emplyoyeeTracker\env\Lib\site-packages\fastapi\routing.py", line 212, in run_endpoint_function
    return await dependant.call(**values)
           ^^^^^^^^^^^^^^^^^^^^^^^^^^^^^^
  File "C:\Users\SHADO\OneDrive\Desktop\emplyoyeeTracker\src\routes\EmployeeRouter.py", line 31, in createEmployee
    return await login_company_controller(employee=employee, session=session)
                 ^^^^^^^^^^^^^^^^^^^^^^^^^^^^^^^^^^^^^^^^^^^^^^^^^^^^^^^^^^^^
TypeError: login_company_controller() got an unexpected keyword argument 'employee'
 
2025-06-29 12:14:53,708 - INFO - Session Has Been Closed 12:14:42 
2025-06-29 12:15:13,124 - INFO - Session Has Been Closed 12:14:42 
2025-06-29 12:15:13,133 - ERROR - [ba4f62c5-4ab7-4f76-92a2-949af21ae300] Internal error: Traceback (most recent call last):
  File "C:\Users\SHADO\OneDrive\Desktop\emplyoyeeTracker\env\Lib\site-packages\starlette\middleware\errors.py", line 165, in __call__
    await self.app(scope, receive, _send)
  File "C:\Users\SHADO\OneDrive\Desktop\emplyoyeeTracker\env\Lib\site-packages\starlette\middleware\cors.py", line 85, in __call__
    await self.app(scope, receive, send)
  File "C:\Users\SHADO\OneDrive\Desktop\emplyoyeeTracker\env\Lib\site-packages\starlette\middleware\exceptions.py", line 62, in __call__
    await wrap_app_handling_exceptions(self.app, conn)(scope, receive, send)
  File "C:\Users\SHADO\OneDrive\Desktop\emplyoyeeTracker\env\Lib\site-packages\starlette\_exception_handler.py", line 53, in wrapped_app
    raise exc
  File "C:\Users\SHADO\OneDrive\Desktop\emplyoyeeTracker\env\Lib\site-packages\starlette\_exception_handler.py", line 42, in wrapped_app
    await app(scope, receive, sender)
  File "C:\Users\SHADO\OneDrive\Desktop\emplyoyeeTracker\env\Lib\site-packages\starlette\routing.py", line 714, in __call__
    await self.middleware_stack(scope, receive, send)
  File "C:\Users\SHADO\OneDrive\Desktop\emplyoyeeTracker\env\Lib\site-packages\starlette\routing.py", line 734, in app
    await route.handle(scope, receive, send)
  File "C:\Users\SHADO\OneDrive\Desktop\emplyoyeeTracker\env\Lib\site-packages\starlette\routing.py", line 288, in handle
    await self.app(scope, receive, send)
  File "C:\Users\SHADO\OneDrive\Desktop\emplyoyeeTracker\env\Lib\site-packages\starlette\routing.py", line 76, in app
    await wrap_app_handling_exceptions(app, request)(scope, receive, send)
  File "C:\Users\SHADO\OneDrive\Desktop\emplyoyeeTracker\env\Lib\site-packages\starlette\_exception_handler.py", line 53, in wrapped_app
    raise exc
  File "C:\Users\SHADO\OneDrive\Desktop\emplyoyeeTracker\env\Lib\site-packages\starlette\_exception_handler.py", line 42, in wrapped_app
    await app(scope, receive, sender)
  File "C:\Users\SHADO\OneDrive\Desktop\emplyoyeeTracker\env\Lib\site-packages\starlette\routing.py", line 73, in app
    response = await f(request)
               ^^^^^^^^^^^^^^^^
  File "C:\Users\SHADO\OneDrive\Desktop\emplyoyeeTracker\env\Lib\site-packages\fastapi\routing.py", line 301, in app
    raw_response = await run_endpoint_function(
                   ^^^^^^^^^^^^^^^^^^^^^^^^^^^^
  File "C:\Users\SHADO\OneDrive\Desktop\emplyoyeeTracker\env\Lib\site-packages\fastapi\routing.py", line 212, in run_endpoint_function
    return await dependant.call(**values)
           ^^^^^^^^^^^^^^^^^^^^^^^^^^^^^^
  File "C:\Users\SHADO\OneDrive\Desktop\emplyoyeeTracker\src\routes\EmployeeRouter.py", line 39, in authenticatedEmployee
    session=session, userId=employee["id"]
                            ~~~~~~~~^^^^^^
TypeError: 'EmployeeLogin' object is not subscriptable
 
2025-06-29 12:27:49,081 - INFO - Session Has Been Closed 12:27:22 
2025-06-29 12:27:49,499 - ERROR - [37e08fac-2a4d-437b-80a3-3b9ae176f74c] Internal error: Traceback (most recent call last):
  File "C:\Users\SHADO\OneDrive\Desktop\emplyoyeeTracker\env\Lib\site-packages\starlette\middleware\errors.py", line 165, in __call__
    await self.app(scope, receive, _send)
  File "C:\Users\SHADO\OneDrive\Desktop\emplyoyeeTracker\env\Lib\site-packages\starlette\middleware\cors.py", line 85, in __call__
    await self.app(scope, receive, send)
  File "C:\Users\SHADO\OneDrive\Desktop\emplyoyeeTracker\env\Lib\site-packages\starlette\middleware\exceptions.py", line 62, in __call__
    await wrap_app_handling_exceptions(self.app, conn)(scope, receive, send)
  File "C:\Users\SHADO\OneDrive\Desktop\emplyoyeeTracker\env\Lib\site-packages\starlette\_exception_handler.py", line 53, in wrapped_app
    raise exc
  File "C:\Users\SHADO\OneDrive\Desktop\emplyoyeeTracker\env\Lib\site-packages\starlette\_exception_handler.py", line 42, in wrapped_app
    await app(scope, receive, sender)
  File "C:\Users\SHADO\OneDrive\Desktop\emplyoyeeTracker\env\Lib\site-packages\starlette\routing.py", line 714, in __call__
    await self.middleware_stack(scope, receive, send)
  File "C:\Users\SHADO\OneDrive\Desktop\emplyoyeeTracker\env\Lib\site-packages\starlette\routing.py", line 734, in app
    await route.handle(scope, receive, send)
  File "C:\Users\SHADO\OneDrive\Desktop\emplyoyeeTracker\env\Lib\site-packages\starlette\routing.py", line 288, in handle
    await self.app(scope, receive, send)
  File "C:\Users\SHADO\OneDrive\Desktop\emplyoyeeTracker\env\Lib\site-packages\starlette\routing.py", line 76, in app
    await wrap_app_handling_exceptions(app, request)(scope, receive, send)
  File "C:\Users\SHADO\OneDrive\Desktop\emplyoyeeTracker\env\Lib\site-packages\starlette\_exception_handler.py", line 53, in wrapped_app
    raise exc
  File "C:\Users\SHADO\OneDrive\Desktop\emplyoyeeTracker\env\Lib\site-packages\starlette\_exception_handler.py", line 42, in wrapped_app
    await app(scope, receive, sender)
  File "C:\Users\SHADO\OneDrive\Desktop\emplyoyeeTracker\env\Lib\site-packages\starlette\routing.py", line 73, in app
    response = await f(request)
               ^^^^^^^^^^^^^^^^
  File "C:\Users\SHADO\OneDrive\Desktop\emplyoyeeTracker\env\Lib\site-packages\fastapi\routing.py", line 291, in app
    solved_result = await solve_dependencies(
                    ^^^^^^^^^^^^^^^^^^^^^^^^^
  File "C:\Users\SHADO\OneDrive\Desktop\emplyoyeeTracker\env\Lib\site-packages\fastapi\dependencies\utils.py", line 640, in solve_dependencies
    solved = await run_in_threadpool(call, **solved_result.values)
             ^^^^^^^^^^^^^^^^^^^^^^^^^^^^^^^^^^^^^^^^^^^^^^^^^^^^^
  File "C:\Users\SHADO\OneDrive\Desktop\emplyoyeeTracker\env\Lib\site-packages\starlette\concurrency.py", line 37, in run_in_threadpool
    return await anyio.to_thread.run_sync(func)
           ^^^^^^^^^^^^^^^^^^^^^^^^^^^^^^^^^^^^
  File "C:\Users\SHADO\OneDrive\Desktop\emplyoyeeTracker\env\Lib\site-packages\anyio\to_thread.py", line 56, in run_sync
    return await get_async_backend().run_sync_in_worker_thread(
           ^^^^^^^^^^^^^^^^^^^^^^^^^^^^^^^^^^^^^^^^^^^^^^^^^^^^
  File "C:\Users\SHADO\OneDrive\Desktop\emplyoyeeTracker\env\Lib\site-packages\anyio\_backends\_asyncio.py", line 2470, in run_sync_in_worker_thread
    return await future
           ^^^^^^^^^^^^
  File "C:\Users\SHADO\OneDrive\Desktop\emplyoyeeTracker\env\Lib\site-packages\anyio\_backends\_asyncio.py", line 967, in run
    result = context.run(func, *args)
             ^^^^^^^^^^^^^^^^^^^^^^^^
  File "C:\Users\SHADO\OneDrive\Desktop\emplyoyeeTracker\src\dependency\dependencies.py", line 54, in get_current_employee
    return {"id": employee_found.id, "email": employee_found.company_email}
                                              ^^^^^^^^^^^^^^^^^^^^^^^^^^^^
  File "C:\Users\SHADO\OneDrive\Desktop\emplyoyeeTracker\env\Lib\site-packages\pydantic\main.py", line 991, in __getattr__
    raise AttributeError(f'{type(self).__name__!r} object has no attribute {item!r}')
AttributeError: 'Employee' object has no attribute 'company_email'. Did you mean: 'company_id'?
 
2025-06-29 12:28:36,748 - INFO - Authenticated Employee Found 
2025-06-29 12:28:37,095 - INFO - Session Has Been Closed 12:28:19 
